<?xml version="1.0" ?>
<!-- =================================================================================== -->
<!-- |    This document was autogenerated by xacro from kr60ha.xacro                   | -->
<!-- |    EDITING THIS FILE BY HAND IS NOT RECOMMENDED                                 | -->
<!-- =================================================================================== -->
<!--Generates a urdf from the macro in kr60ha_macro.xacro -->
<robot name="torso">
  <!-- LINKS -->
  <!-- base link -->
  <link name="base_link">
  </link>
  <!-- link 1 (A1) -->
  <link name="link_torso">
    <inertial>
      <origin rpy="0 0 0" xyz="0 0 0.05"/>
      <mass value="2"/>
      <inertia ixx="0.01" ixy="0" ixz="0" iyy="0.01" iyz="0" izz="0.01"/>
    </inertial>
		<visual>
		      <origin rpy="0 0 0" xyz="0 0 0"/>
		      <geometry>
						<mesh filename="cube.obj" scale="0.2 0.6 0.1"/>
		      </geometry>
		       <material name="red">
		        <color rgba="0.8 0.2 0 1"/>
		      </material>
		</visual>
		<collision>
		      <origin rpy="0 0 0" xyz="0 0 0"/>
		      <geometry>
			 	<box size="0.2 0.6 0.1"/>
		      </geometry>
		</collision>
  </link>

	<joint name="j_torso" type="revolute">
    <origin rpy="0 0 0" xyz="0 0 0"/>
    <parent link="base_link"/>
    <child link="link_torso"/>
    <axis xyz="0 0 1"/>
    <limit effort="100" lower="-3.22885911619" upper="3.22885911619" velocity="2.23402144255"/>
  </joint>
	</robot>
